Workbook

Sheet README
B2: VACATION TRACKER — README
B5: STRUCTURE
B6: Year Summary rolls up totals across every destination tab.
B7: Destination tabs (Singapore 2026, Montreal 2026, Spain 2026, Japan 2027) log flights, hotels, activities directly.
B8: Cards credit card AF / signup bonus tracker.
B9: 3% Fee Tracker non-bonus spend that earns points worth more than the 3% fee.
B10: CPP Calculator quick check whether a redemption beats your target CPP.
B12: HOW TO LOG A TRIP
B13: 1. Pick the destination tab.
B14: 2. Under FLIGHTS, fill in Date, Airline, Route, Class, Points, Tax + Fee, Sticker, Notes.
B15: 3. Under HOTELS, fill in Check-in, Hotel, Location, Nights, Points, Tax + Fee, Sticker, Notes.
B16: 4. Under ACTIVITIES, fill in Date, Activity, Vendor, Travelers, Cash, Currency, Category, Notes.
... B40: 3% Fee Tracker uses CPP from M6 update it if your point value changes.

Sheet Year Summary
B2: VACATION YEAR SUMMARY
N3: HELPER (do not edit)
B4: Year | C4: 2026 | E4: Change the Year cell to filter the totals below. | N4: Trip | O4: Year | P4: Trip Cost | Q4: Cash on Red. | R4: Activities | S4: Points | T4: Sticker | U4: Savings | V4: Airline Pts | W4: Hotel Pts | X4: Air W | Y4: Hot W
N5: Singapore 2026 | O5: 2026 | P5: ='Singapore 2026'!B8 -> 4364.94 | Q5: ='Singapore 2026'!E8 -> 4364.94 | R5: ='Singapore 2026'!H8 -> 0 | S5: ='Singapore 2026'!J8 -> 726000 | T5: ='Singapore 2026'!B11 -> 38563.34 | U5: ='Singapore 2026'!E11 -> 34198.4 | V5: ='Singapore 2026'!B14 -> 726000 | W5: ='Singapore 2026'!H14 -> 0 | X5: ='Singapore 2026'!B14*'Singapore 2026'!E14 -> 3211229 | Y5: ='Singapore 2026'!H14*'Singapore 2026'!J14 -> 0
B6: =" TOTALS FOR " & TEXT($C$4,"0") -> TOTALS FOR 2026 | N6: Montreal 2026 | O6: 2026 | P6: ='Montreal 2026'!B8 -> 328.92 | Q6: ='Montreal 2026'!E8 -> 328.92 | R6: ='Montreal 2026'!H8 -> 0 | S6: ='Montreal 2026'!J8 -> 0 | T6: ='Montreal 2026'!B11 -> 1228.92 | U6: ='Montreal 2026'!E11 -> 900 | V6: ='Montreal 2026'!B14 -> 0 | W6: ='Montreal 2026'!H14 -> 0 | X6: ='Montreal 2026'!B14*'Montreal 2026'!E14 -> 0 | Y6: ='Montreal 2026'!H14*'Montreal 2026'!J14 -> 0
B7: Total Vacation Spend | D7: Cash on Redemptions | F7: Activities Cash | H7: Points Used | N7: Spain 2026 | O7: 2026 | P7: ='Spain 2026'!B8 -> 5480.24 | Q7: ='Spain 2026'!E8 -> 3547.34 | R7: ='Spain 2026'!H8 -> 1932.9 | S7: ='Spain 2026'!J8 -> 438000 | T7: ='Spain 2026'!B11 -> 31222.94 | U7: ='Spain 2026'!E11 -> 27675.6 | V7: ='Spain 2026'!B14 -> 438000 | W7: ='Spain 2026'!H14 -> 0 | X7: ='Spain 2026'!B14*'Spain 2026'!E14 -> 2662560 | Y7: ='Spain 2026'!H14*'Spain 2026'!J14 -> 0
B8: =SUMIFS(P5:P18,O5:O18,$C$4) -> 10174.1 | D8: =SUMIFS(Q5:Q18,O5:O18,$C$4) -> 8241.2 | F8: =SUMIFS(R5:R18,O5:O18,$C$4) -> 1932.9 | H8: =SUMIFS(S5:S18,O5:O18,$C$4) -> 1164000 | N8: Japan 2027 | O8: 2027 | P8: ='Japan 2027'!B8 -> 1320 | Q8: ='Japan 2027'!E8 -> 0 | R8: ='Japan 2027'!H8 -> 1320 | S8: ='Japan 2027'!J8 -> 0 | T8: ='Japan 2027'!B11 -> 0 | U8: ='Japan 2027'!E11 -> 0 | V8: ='Japan 2027'!B14 -> 0 | W8: ='Japan 2027'!H14 -> 0 | X8: ='Japan 2027'!B14*'Japan 2027'!E14 -> 0 | Y8: ='Japan 2027'!H14*'Japan 2027'!J14 -> 0
N9: (add trip name) | O9: (year)
B10: Sticker Value | D10: Total Savings | F10: Blended CPP | H10: % Off Sticker | N10: (add trip name) | O10: (year)
B11: =SUMIFS(T5:T18,O5:O18,$C$4) -> 71015.2 | D11: =SUMIFS(U5:U18,O5:O18,$C$4) -> 62774 | F11: =IFERROR(SUMIFS(U5:U18,O5:O18,$C$4)/SUMIFS(S5:S18,O5:O18,$C$4)*100,0) -> 5.3929553 | H11: =IFERROR(SUMIFS(U5:U18,O5:O18,$C$4)/SUMIFS(T5:T18,O5:O18,$C$4),0) -> 0.8839516 | N11: (add trip name) | O11: (year)
N12: (add trip name) | O12: (year)
B13: Airline Points | D13: Airline CPP | F13: Hotel Points | H13: Hotel CPP | N13: (add trip name) | O13: (year)
B14: =SUMIFS(V5:V18,O5:O18,$C$4) -> 1164000 | D14: =IFERROR(SUMIFS(X5:X18,O5:O18,$C$4)/SUMIFS(V5:V18,O5:O18,$C$4),0) -> 5.0462105 | F14: =SUMIFS(W5:W18,O5:O18,$C$4) -> 0 | H14: =IFERROR(SUMIFS(Y5:Y18,O5:O18,$C$4)/SUMIFS(W5:W18,O5:O18,$C$4),0) -> 0 | N14: (add trip name) | O14: (year)
N15: (add trip name) | O15: (year)
N16: (add trip name) | O16: (year)
B17: BY TRIP — GROUPED BY YEAR | N17: (add trip name) | O17: (year)
B18: Trip | C18: Trip Cost ($) | D18: Activities ($) | E18: Sticker ($) | F18: Points Used | G18: Savings ($) | H18: Blended CPP (¢) | I18: Airline CPP (¢) | J18: Hotel CPP (¢) | N18: (add trip name) | O18: (year)
B19: 2026
B20: Singapore 2026 | C20: ='Singapore 2026'!B8 -> 4364.94 | D20: ='Singapore 2026'!H8 -> 0 | E20: ='Singapore 2026'!B11 -> 38563.34 | F20: ='Singapore 2026'!J8 -> 726000 | G20: ='Singapore 2026'!E11 -> 34198.4 | H20: ='Singapore 2026'!H11 -> 4.7105234 | I20: ='Singapore 2026'!E14 -> 4.4231804 | J20: ='Singapore 2026'!J14 -> 0
B21: Montreal 2026 | C21: ='Montreal 2026'!B8 -> 328.92 | D21: ='Montreal 2026'!H8 -> 0 | E21: ='Montreal 2026'!B11 -> 1228.92 | F21: ='Montreal 2026'!J8 -> 0 | G21: ='Montreal 2026'!E11 -> 900 | H21: ='Montreal 2026'!H11 -> 0 | I21: ='Montreal 2026'!E14 -> 0 | J21: ='Montreal 2026'!J14 -> 0
B22: Spain 2026 | C22: ='Spain 2026'!B8 -> 5480.24 | D22: ='Spain 2026'!H8 -> 1932.9 | E22: ='Spain 2026'!B11 -> 31222.94 | F22: ='Spain 2026'!J8 -> 438000 | G22: ='Spain 2026'!E11 -> 27675.6 | H22: ='Spain 2026'!H11 -> 6.3186301 | I22: ='Spain 2026'!E14 -> 6.0789041 | J22: ='Spain 2026'!J14 -> 0
B23: (add trip)
B24: (add trip)
B25: (add trip)
B26: (add trip)
B27: (add trip)
B28: 2026 subtotal | C28: =SUM(C20:C27) -> 10174.1 | D28: =SUM(D20:D27) -> 1932.9 | E28: =SUM(E20:E27) -> 71015.2 | F28: =SUM(F20:F27) -> 1164000 | G28: =SUM(G20:G27) -> 62774 | H28: =IFERROR(SUM(G20:G27)/SUM(F20:F27)*100,0) -> 5.3929553 | I28: =IFERROR(('Singapore 2026'!B14*'Singapore 2026'!E14+'Montreal 2026'!B14*'Montreal 2026'!E14+'Spain 2026'!B14*'Spain 2026'!E14)/('Singapore 2026'!B14+'Montreal 2026'!B14+'Spain 2026'!B14),0) -> 5.0462105 | J28: =IFERROR(('Singapore 2026'!H14*'Singapore 2026'!J14+'Montreal 2026'!H14*'Montreal 2026'!J14+'Spain 2026'!H14*'Spain 2026'!J14)/('Singapore 2026'!H14+'Montreal 2026'!H14+'Spain 2026'!H14),0) -> 0
B30: 2027
B31: Japan 2027 | C31: ='Japan 2027'!B8 -> 1320 | D31: ='Japan 2027'!H8 -> 1320 | E31: ='Japan 2027'!B11 -> 0 | F31: ='Japan 2027'!J8 -> 0 | G31: ='Japan 2027'!E11 -> 0 | H31: ='Japan 2027'!H11 -> 0 | I31: ='Japan 2027'!E14 -> 0 | J31: ='Japan 2027'!J14 -> 0
B32: (add trip)
B33: (add trip)
B34: (add trip)
B35: (add trip)
B36: (add trip)
B37: 2027 subtotal | C37: =SUM(C31:C36) -> 1320 | D37: =SUM(D31:D36) -> 1320 | E37: =SUM(E31:E36) -> 0 | F37: =SUM(F31:F36) -> 0 | G37: =SUM(G31:G36) -> 0 | H37: =IFERROR(SUM(G31:G36)/SUM(F31:F36)*100,0) -> 0 | I37: =IFERROR(('Japan 2027'!B14*'Japan 2027'!E14)/('Japan 2027'!B14),0) -> 0 | J37: =IFERROR(('Japan 2027'!H14*'Japan 2027'!J14)/('Japan 2027'!H14),0) -> 0
B39: GRAND TOTAL | C39: =SUM(C28,C37) -> 11494.1 | D39: =SUM(D28,D37) -> 3252.9 | E39: =SUM(E28,E37) -> 71015.2 | F39: =SUM(F28,F37) -> 1164000 | G39: =SUM(G28,G37) -> 62774 | H39: =IFERROR(SUM(U5:U18)/SUM(S5:S18)*100,0) -> 5.3929553 | I39: =IFERROR(SUM(X5:X18)/SUM(V5:V18),0) -> 5.0462105 | J39: =IFERROR(SUM(Y5:Y18)/SUM(W5:W18),0) -> 0
B42: CARDS & FEES
B43: Net Card Profit | E43: =SUM(Cards!K6:K30) -> #VALUE!
B44: 3% Fee Spend (Total) | E44: ='3% Fee Tracker'!G61 -> 20000
B45: 3% Fee Paid (Total) | E45: ='3% Fee Tracker'!I61 -> 455.5
...

Sheet Singapore 2026
B2: SINGAPORE 2026
B4: Trip Name | C4: Singapore Trip | E4: Dates | F4: Apr 15 - Apr 26, 2026 | I4: Notes | J4: Singapore + Fuzhou with kids
B6: TRIP SUMMARY
B7: Total Trip Cost | E7: Cash on Redemptions | H7: Activities Cash | J7: Points Used
B8: =SUM(G18:G32)+SUM(G36:G50)+SUM(H54:H68) -> 4364.94 | E8: =SUM(G18:G32)+SUM(G36:G50) -> 4364.94 | H8: =SUM(H54:H68) -> 0 | J8: =SUM(F18:F32)+SUM(F36:F50) -> 726000
B10: Sticker Value | E10: Total Savings | H10: Blended CPP | J10: % Off Sticker
B11: =SUM(H18:H32)+SUM(H36:H50) -> 38563.34 | E11: =IFERROR((SUM(H18:H32)+SUM(H36:H50))-(SUM(G18:G32)+SUM(G36:G50)),0) -> 34198.4 | H11: =IFERROR(E11/J8*100,0) -> 4.7105234 | J11: =IFERROR(E11/B11,0) -> 0.88681115
B13: Airline Points | E13: Airline CPP | H13: Hotel Points | J13: Hotel CPP
B14: =SUM(F18:F32) -> 726000 | E14: =IFERROR((SUM(H18:H32)-SUM(G18:G32))/SUM(F18:F32)*100,0) -> 4.4231804 | H14: =SUM(F36:F50) -> 0 | J14: =IFERROR((SUM(H36:H50)-SUM(G36:G50))/SUM(F36:F50)*100,0) -> 0
B16: FLIGHTS
B17: Date | C17: Airline | D17: Route | E17: Class | F17: Points | G17: Tax + Fee ($) | H17: Sticker ($) | I17: CPP (¢) | J17: Savings ($) | K17: % Off | L17: Notes
B18: 46127 | C18: SQ via Aeroplan | D18: JFK-SIN | E18: Business | F18: 140000 | G18: 589.01 | H18: 8390 | I18: =IF(OR(F18="",F18=0,H18="",H18=0),"",(H18-G18)/F18*100) -> 5.5721357 | J18: =IF(OR(H18="",H18=0),"",MAX(H18-G18,0)) -> 7800.99 | K18: =IF(OR(H18="",H18=0),"",MAX((H18-G18)/H18,0)) -> 0.92979619 | L18: Aeroplan award
B19: 46127 | C19: SQ via KrisFlyer | D19: JFK-SIN | E19: Business | F19: 223000 | G19: 11.2 | H19: 8390 | I19: =IF(OR(F19="",F19=0,H19="",H19=0),"",(H19-G19)/F19*100) -> 3.7573094 | J19: =IF(OR(H19="",H19=0),"",MAX(H19-G19,0)) -> 8378.8 | K19: =IF(OR(H19="",H19=0),"",MAX((H19-G19)/H19,0)) -> 0.99866508 | L19: KrisFlyer
B20: 46146 | C20: SQ via Aeroplan | D20: SIN-JFK | E20: Business | F20: 140000 | G20: 717 | H20: 8390 | I20: =IF(OR(F20="",F20=0,H20="",H20=0),"",(H20-G20)/F20*100) -> 5.4807143 | J20: =IF(OR(H20="",H20=0),"",MAX(H20-G20,0)) -> 7673 | K20: =IF(OR(H20="",H20=0),"",MAX((H20-G20)/H20,0)) -> 0.91454112 | L20: Aeroplan return
B21: 46146 | C21: SQ via KrisFlyer | D21: SIN-JFK | E21: Business | F21: 223000 | G21: 130.5 | H21: 8390 | I21: =IF(OR(F21="",F21=0,H21="",H21=0),"",(H21-G21)/F21*100) -> 3.7038117 | J21: =IF(OR(H21="",H21=0),"",MAX(H21-G21,0)) -> 8259.5 | K21: =IF(OR(H21="",H21=0),"",MAX((H21-G21)/H21,0)) -> 0.98444577 | L21: KrisFlyer return
B22: 46132 | C22: SIN-FOC (cash) | D22: Singapore-Fuzhou | E22: Economy | F22: 0 | G22: 1712.2 | H22: 1712.2 | I22: =IF(OR(F22="",F22=0,H22="",H22=0),"",(H22-G22)/F22*100) | J22: =IF(OR(H22="",H22=0),"",MAX(H22-G22,0)) -> 0 | K22: =IF(OR(H22="",H22=0),"",MAX((H22-G22)/H22,0)) -> 0 | L22: Paid cash
I23: =IF(OR(F23="",F23=0,H23="",H23=0),"",(H23-G23)/F23*100) | J23: =IF(OR(H23="",H23=0),"",MAX(H23-G23,0)) | K23: =IF(OR(H23="",H23=0),"",MAX((H23-G23)/H23,0))
I24: =IF(OR(F24="",F24=0,H24="",H24=0),"",(H24-G24)/F24*100) | J24: =IF(OR(H24="",H24=0),"",MAX(H24-G24,0)) | K24: =IF(OR(H24="",H24=0),"",MAX((H24-G24)/H24,0))
I25: =IF(OR(F25="",F25=0,H25="",H25=0),"",(H25-G25)/F25*100) | J25: =IF(OR(H25="",H25=0),"",MAX(H25-G25,0)) | K25: =IF(OR(H25="",H25=0),"",MAX((H25-G25)/H25,0))
I26: =IF(OR(F26="",F26=0,H26="",H26=0),"",(H26-G26)/F26*100) | J26: =IF(OR(H26="",H26=0),"",MAX(H26-G26,0)) | K26: =IF(OR(H26="",H26=0),"",MAX((H26-G26)/H26,0))
I27: =IF(OR(F27="",F27=0,H27="",H27=0),"",(H27-G27)/F27*100) | J27: =IF(OR(H27="",H27=0),"",MAX(H27-G27,0)) | K27: =IF(OR(H27="",H27=0),"",MAX((H27-G27)/H27,0))
I28: =IF(OR(F28="",F28=0,H28="",H28=0),"",(H28-G28)/F28*100) | J28: =IF(OR(H28="",H28=0),"",MAX(H28-G28,0)) | K28: =IF(OR(H28="",H28=0),"",MAX((H28-G28)/H28,0))
I29: =IF(OR(F29="",F29=0,H29="",H29=0),"",(H29-G29)/F29*100) | J29: =IF(OR(H29="",H29=0),"",MAX(H29-G29,0)) | K29: =IF(OR(H29="",H29=0),"",MAX((H29-G29)/H29,0))
I30: =IF(OR(F30="",F30=0,H30="",H30=0),"",(H30-G30)/F30*100) | J30: =IF(OR(H30="",H30=0),"",MAX(H30-G30,0)) | K30: =IF(OR(H30="",H30=0),"",MAX((H30-G30)/H30,0))
I31: =IF(OR(F31="",F31=0,H31="",H31=0),"",(H31-G31)/F31*100) | J31: =IF(OR(H31="",H31=0),"",MAX(H31-G31,0)) | K31: =IF(OR(H31="",H31=0),"",MAX((H31-G31)/H31,0))
I32: =IF(OR(F32="",F32=0,H32="",H32=0),"",(H32-G32)/F32*100) | J32: =IF(OR(H32="",H32=0),"",MAX(H32-G32,0)) | K32: =IF(OR(H32="",H32=0),"",MAX((H32-G32)/H32,0))
B34: HOTELS
B35: Check-in | C35: Hotel | D35: Location | E35: Nights | F35: Points | G35: Tax + Fee ($) | H35: Sticker ($) | I35: CPP (¢) | J35: Savings ($) | K35: % Off | L35: Notes
B36: 46127 | C36: Shangri-La SIN | D36: Singapore | E36: 4 | F36: 0 | G36: 357.44 | H36: 1080.57 | I36: =IF(OR(F36="",F36=0,H36="",H36=0),"",(H36-G36)/F36*100) | J36: =IF(OR(H36="",H36=0),"",MAX(H36-G36,0)) -> 723.13 | K36: =IF(OR(H36="",H36=0),"",MAX((H36-G36)/H36,0)) -> 0.66921162 | L36: FHR Credit
B37: 46131 | C37: Shangri-La FOC | D37: Fuzhou | E37: 4 | F37: 0 | G37: 30 | H37: 330 | I37: =IF(OR(F37="",F37=0,H37="",H37=0),"",(H37-G37)/F37*100) | J37: =IF(OR(H37="",H37=0),"",MAX(H37-G37,0)) -> 300 | K37: =IF(OR(H37="",H37=0),"",MAX((H37-G37)/H37,0)) -> 0.90909091 | L37: Cap X credit
B38: 46135 | C38: Hilton FOC | D38: Fuzhou | E38: 3 | F38: 0 | G38: 800 | H38: 800 | I38: =IF(OR(F38="",F38=0,H38="",H38=0),"",(H38-G38)/F38*100) | J38: =IF(OR(H38="",H38=0),"",MAX(H38-G38,0)) -> 0 | K38: =IF(OR(H38="",H38=0),"",MAX((H38-G38)/H38,0)) -> 0 | L38: Cash
B39: 46145 | C39: Shangri-La SIN | D39: Singapore | E39: 1 | F39: 0 | G39: 17.59 | H39: 1080.57 | I39: =IF(OR(F39="",F39=0,H39="",H39=0),"",(H39-G39)/F39*100) | J39: =IF(OR(H39="",H39=0),"",MAX(H39-G39,0)) -> 1062.98 | K39: =IF(OR(H39="",H39=0),"",MAX((H39-G39)/H39,0)) -> 0.98372155 | L39: FHR Credit
I40: =IF(OR(F40="",F40=0,H40="",H40=0),"",(H40-G40)/F40*100) | J40: =IF(OR(H40="",H40=0),"",MAX(H40-G40,0)) | K40: =IF(OR(H40="",H40=0),"",MAX((H40-G40)/H40,0))
I41: =IF(OR(F41="",F41=0,H41="",H41=0),"",(H41-G41)/F41*100) | J41: =IF(OR(H41="",H41=0),"",MAX(H41-G41,0)) | K41: =IF(OR(H41="",H41=0),"",MAX((H41-G41)/H41,0))
I42: =IF(OR(F42="",F42=0,H42="",H42=0),"",(H42-G42)/F42*100) | J42: =IF(OR(H42="",H42=0),"",MAX(H42-G42,0)) | K42: =IF(OR(H42="",H42=0),"",MAX((H42-G42)/H42,0))
I43: =IF(OR(F43="",F43=0,H43="",H43=0),"",(H43-G43)/F43*100) | J43: =IF(OR(H43="",H43=0),"",MAX(H43-G43,0)) | K43: =IF(OR(H43="",H43=0),"",MAX((H43-G43)/H43,0))
I44: =IF(OR(F44="",F44=0,H44="",H44=0),"",(H44-G44)/F44*100) | J44: =IF(OR(H44="",H44=0),"",MAX(H44-G44,0)) | K44: =IF(OR(H44="",H44=0),"",MAX((H44-G44)/H44,0))
I45: =IF(OR(F45="",F45=0,H45="",H45=0),"",(H45-G45)/F45*100) | J45: =IF(OR(H45="",H45=0),"",MAX(H45-G45,0)) | K45: =IF(OR(H45="",H45=0),"",MAX((H45-G45)/H45,0))
I46: =IF(OR(F46="",F46=0,H46="",H46=0),"",(H46-G46)/F46*100) | J46: =IF(OR(H46="",H46=0),"",MAX(H46-G46,0)) | K46: =IF(OR(H46="",H46=0),"",MAX((H46-G46)/H46,0))
I47: =IF(OR(F47="",F47=0,H47="",H47=0),"",(H47-G47)/F47*100) | J47: =IF(OR(H47="",H47=0),"",MAX(H47-G47,0)) | K47: =IF(OR(H47="",H47=0),"",MAX((H47-G47)/H47,0))
...

Sheet Montreal 2026
B2: MONTREAL 2026
B4: Trip Name | C4: Montreal Trip | E4: Dates | F4: Feb 12 - Feb 17, 2026 | I4: Notes | J4: Omni Mont-Royal
B6: TRIP SUMMARY
B7: Total Trip Cost | E7: Cash on Redemptions | H7: Activities Cash | J7: Points Used
B8: =SUM(G18:G32)+SUM(G36:G50)+SUM(H54:H68) -> 328.92 | E8: =SUM(G18:G32)+SUM(G36:G50) -> 328.92 | H8: =SUM(H54:H68) -> 0 | J8: =SUM(F18:F32)+SUM(F36:F50) -> 0
B10: Sticker Value | E10: Total Savings | H10: Blended CPP | J10: % Off Sticker
B11: =SUM(H18:H32)+SUM(H36:H50) -> 1228.92 | E11: =IFERROR((SUM(H18:H32)+SUM(H36:H50))-(SUM(G18:G32)+SUM(G36:G50)),0) -> 900 | H11: =IFERROR(E11/J8*100,0) -> 0 | J11: =IFERROR(E11/B11,0) -> 0.73235036
B13: Airline Points | E13: Airline CPP | H13: Hotel Points | J13: Hotel CPP
B14: =SUM(F18:F32) -> 0 | E14: =IFERROR((SUM(H18:H32)-SUM(G18:G32))/SUM(F18:F32)*100,0) -> 0 | H14: =SUM(F36:F50) -> 0 | J14: =IFERROR((SUM(H36:H50)-SUM(G36:G50))/SUM(F36:F50)*100,0) -> 0
B16: FLIGHTS
B17: Date | C17: Airline | D17: Route | E17: Class | F17: Points | G17: Tax + Fee ($) | H17: Sticker ($) | I17: CPP (¢) | J17: Savings ($) | K17: % Off | L17: Notes
I18: =IF(OR(F18="",F18=0,H18="",H18=0),"",(H18-G18)/F18*100) | J18: =IF(OR(H18="",H18=0),"",MAX(H18-G18,0)) | K18: =IF(OR(H18="",H18=0),"",MAX((H18-G18)/H18,0))
I19: =IF(OR(F19="",F19=0,H19="",H19=0),"",(H19-G19)/F19*100) | J19: =IF(OR(H19="",H19=0),"",MAX(H19-G19,0)) | K19: =IF(OR(H19="",H19=0),"",MAX((H19-G19)/H19,0))
I20: =IF(OR(F20="",F20=0,H20="",H20=0),"",(H20-G20)/F20*100) | J20: =IF(OR(H20="",H20=0),"",MAX(H20-G20,0)) | K20: =IF(OR(H20="",H20=0),"",MAX((H20-G20)/H20,0))
I21: =IF(OR(F21="",F21=0,H21="",H21=0),"",(H21-G21)/F21*100) | J21: =IF(OR(H21="",H21=0),"",MAX(H21-G21,0)) | K21: =IF(OR(H21="",H21=0),"",MAX((H21-G21)/H21,0))
I22: =IF(OR(F22="",F22=0,H22="",H22=0),"",(H22-G22)/F22*100) | J22: =IF(OR(H22="",H22=0),"",MAX(H22-G22,0)) | K22: =IF(OR(H22="",H22=0),"",MAX((H22-G22)/H22,0))
I23: =IF(OR(F23="",F23=0,H23="",H23=0),"",(H23-G23)/F23*100) | J23: =IF(OR(H23="",H23=0),"",MAX(H23-G23,0)) | K23: =IF(OR(H23="",H23=0),"",MAX((H23-G23)/H23,0))
I24: =IF(OR(F24="",F24=0,H24="",H24=0),"",(H24-G24)/F24*100) | J24: =IF(OR(H24="",H24=0),"",MAX(H24-G24,0)) | K24: =IF(OR(H24="",H24=0),"",MAX((H24-G24)/H24,0))
I25: =IF(OR(F25="",F25=0,H25="",H25=0),"",(H25-G25)/F25*100) | J25: =IF(OR(H25="",H25=0),"",MAX(H25-G25,0)) | K25: =IF(OR(H25="",H25=0),"",MAX((H25-G25)/H25,0))
I26: =IF(OR(F26="",F26=0,H26="",H26=0),"",(H26-G26)/F26*100) | J26: =IF(OR(H26="",H26=0),"",MAX(H26-G26,0)) | K26: =IF(OR(H26="",H26=0),"",MAX((H26-G26)/H26,0))
I27: =IF(OR(F27="",F27=0,H27="",H27=0),"",(H27-G27)/F27*100) | J27: =IF(OR(H27="",H27=0),"",MAX(H27-G27,0)) | K27: =IF(OR(H27="",H27=0),"",MAX((H27-G27)/H27,0))
I28: =IF(OR(F28="",F28=0,H28="",H28=0),"",(H28-G28)/F28*100) | J28: =IF(OR(H28="",H28=0),"",MAX(H28-G28,0)) | K28: =IF(OR(H28="",H28=0),"",MAX((H28-G28)/H28,0))
I29: =IF(OR(F29="",F29=0,H29="",H29=0),"",(H29-G29)/F29*100) | J29: =IF(OR(H29="",H29=0),"",MAX(H29-G29,0)) | K29: =IF(OR(H29="",H29=0),"",MAX((H29-G29)/H29,0))
... I32: =IF(OR(F32="",F32=0,H32="",H32=0),"",(H32-G32)/F32*100) | J32: =IF(OR(H32="",H32=0),"",MAX(H32-G32,0)) | K32: =IF(OR(H32="",H32=0),"",MAX((H32-G32)/H32,0))
B34: HOTELS
B35: Check-in | C35: Hotel | D35: Location | E35: Nights | F35: Points | G35: Tax + Fee ($) | H35: Sticker ($) | I35: CPP (¢) | J35: Savings ($) | K35: % Off | L35: Notes
B36: 46065 | C36: Omni Mont-Royal | D36: Montreal | E36: 5 | F36: 0 | G36: 328.92 | H36: 1228.92 | I36: =IF(OR(F36="",F36=0,H36="",H36=0),"",(H36-G36)/F36*100) | J36: =IF(OR(H36="",H36=0),"",MAX(H36-G36,0)) -> 900 | K36: =IF(OR(H36="",H36=0),"",MAX((H36-G36)/H36,0)) -> 0.73235036 | L36: FHR Credit
I37: =IF(OR(F37="",F37=0,H37="",H37=0),"",(H37-G37)/F37*100) | J37: =IF(OR(H37="",H37=0),"",MAX(H37-G37,0)) | K37: =IF(OR(H37="",H37=0),"",MAX((H37-G37)/H37,0))
I38: =IF(OR(F38="",F38=0,H38="",H38=0),"",(H38-G38)/F38*100) | J38: =IF(OR(H38="",H38=0),"",MAX(H38-G38,0)) | K38: =IF(OR(H38="",H38=0),"",MAX((H38-G38)/H38,0))
I39: =IF(OR(F39="",F39=0,H39="",H39=0),"",(H39-G39)/F39*100) | J39: =IF(OR(H39="",H39=0),"",MAX(H39-G39,0)) | K39: =IF(OR(H39="",H39=0),"",MAX((H39-G39)/H39,0))
I40: =IF(OR(F40="",F40=0,H40="",H40=0),"",(H40-G40)/F40*100) | J40: =IF(OR(H40="",H40=0),"",MAX(H40-G40,0)) | K40: =IF(OR(H40="",H40=0),"",MAX((H40-G40)/H40,0))
I41: =IF(OR(F41="",F41=0,H41="",H41=0),"",(H41-G41)/F41*100) | J41: =IF(OR(H41="",H41=0),"",MAX(H41-G41,0)) | K41: =IF(OR(H41="",H41=0),"",MAX((H41-G41)/H41,0))
I42: =IF(OR(F42="",F42=0,H42="",H42=0),"",(H42-G42)/F42*100) | J42: =IF(OR(H42="",H42=0),"",MAX(H42-G42,0)) | K42: =IF(OR(H42="",H42=0),"",MAX((H42-G42)/H42,0))
I43: =IF(OR(F43="",F43=0,H43="",H43=0),"",(H43-G43)/F43*100) | J43: =IF(OR(H43="",H43=0),"",MAX(H43-G43,0)) | K43: =IF(OR(H43="",H43=0),"",MAX((H43-G43)/H43,0))
I44: =IF(OR(F44="",F44=0,H44="",H44=0),"",(H44-G44)/F44*100) | J44: =IF(OR(H44="",H44=0),"",MAX(H44-G44,0)) | K44: =IF(OR(H44="",H44=0),"",MAX((H44-G44)/H44,0))
I45: =IF(OR(F45="",F45=0,H45="",H45=0),"",(H45-G45)/F45*100) | J45: =IF(OR(H45="",H45=0),"",MAX(H45-G45,0)) | K45: =IF(OR(H45="",H45=0),"",MAX((H45-G45)/H45,0))
I46: =IF(OR(F46="",F46=0,H46="",H46=0),"",(H46-G46)/F46*100) | J46: =IF(OR(H46="",H46=0),"",MAX(H46-G46,0)) | K46: =IF(OR(H46="",H46=0),"",MAX((H46-G46)/H46,0))
I47: =IF(OR(F47="",F47=0,H47="",H47=0),"",(H47-G47)/F47*100) | J47: =IF(OR(H47="",H47=0),"",MAX(H47-G47,0)) | K47: =IF(OR(H47="",H47=0),"",MAX((H47-G47)/H47,0))
I48: =IF(OR(F48="",F48=0,H48="",H48=0),"",(H48-G48)/F48*100) | J48: =IF(OR(H48="",H48=0),"",MAX(H48-G48,0)) | K48: =IF(OR(H48="",H48=0),"",MAX((H48-G48)/H48,0))
... I50: =IF(OR(F50="",F50=0,H50="",H50=0),"",(H50-G50)/F50*100) | J50: =IF(OR(H50="",H50=0),"",MAX(H50-G50,0)) | K50: =IF(OR(H50="",H50=0),"",MAX((H50-G50)/H50,0))
...

Sheet Spain 2026
B2: SPAIN 2026
B4: Trip Name | C4: Spain Trip | E4: Dates | F4: Jul 26 - Aug 7, 2026 | I4: Notes | J4: Barcelona / San Sebastian / Valencia
B6: TRIP SUMMARY
B7: Total Trip Cost | E7: Cash on Redemptions | H7: Activities Cash | J7: Points Used
B8: =SUM(G18:G32)+SUM(G36:G50)+SUM(H54:H68) -> 5480.24 | E8: =SUM(G18:G32)+SUM(G36:G50) -> 3547.34 | H8: =SUM(H54:H68) -> 1932.9 | J8: =SUM(F18:F32)+SUM(F36:F50) -> 438000
B10: Sticker Value | E10: Total Savings | H10: Blended CPP | J10: % Off Sticker
B11: =SUM(H18:H32)+SUM(H36:H50) -> 31222.94 | E11: =IFERROR((SUM(H18:H32)+SUM(H36:H50))-(SUM(G18:G32)+SUM(G36:G50)),0) -> 27675.6 | H11: =IFERROR(E11/J8*100,0) -> 6.3186301 | J11: =IFERROR(E11/B11,0) -> 0.88638674
B13: Airline Points | E13: Airline CPP | H13: Hotel Points | J13: Hotel CPP
B14: =SUM(F18:F32) -> 438000 | E14: =IFERROR((SUM(H18:H32)-SUM(G18:G32))/SUM(F18:F32)*100,0) -> 6.0789041 | H14: =SUM(F36:F50) -> 0 | J14: =IFERROR((SUM(H36:H50)-SUM(G36:G50))/SUM(F36:F50)*100,0) -> 0
B16: FLIGHTS
B17: Date | C17: Airline | D17: Route | E17: Class | F17: Points | G17: Tax + Fee ($) | H17: Sticker ($) | I17: CPP (¢) | J17: Savings ($) | K17: % Off | L17: Notes
B18: 46230 | C18: Drive/Train | D18: JFK-BOS positioning | E18: Cash | F18: 0 | G18: 0 | H18: 0 | I18: =IF(OR(F18="",F18=0,H18="",H18=0),"",(H18-G18)/F18*100) | J18: =IF(OR(H18="",H18=0),"",MAX(H18-G18,0)) | K18: =IF(OR(H18="",H18=0),"",MAX((H18-G18)/H18,0)) | L18: Drive/train
B19: 46231 | C19: Alaska | D19: BOS-BCN | E19: Business | F19: 170000 | G19: 22.4 | H19: 15200 | I19: =IF(OR(F19="",F19=0,H19="",H19=0),"",(H19-G19)/F19*100) -> 8.928 | J19: =IF(OR(H19="",H19=0),"",MAX(H19-G19,0)) -> 15177.6 | K19: =IF(OR(H19="",H19=0),"",MAX((H19-G19)/H19,0)) -> 0.99852632 | L19: Sweet spot via ATMOS
B20: 46235 | C20: Vueling | D20: BCN-BIO | E20: Economy | F20: 0 | G20: 423.2 | H20: 423.2 | I20: =IF(OR(F20="",F20=0,H20="",H20=0),"",(H20-G20)/F20*100) | J20: =IF(OR(H20="",H20=0),"",MAX(H20-G20,0)) -> 0 | K20: =IF(OR(H20="",H20=0),"",MAX((H20-G20)/H20,0)) -> 0 | L20: VY1430 AF37KV
B21: 46238 | C21: Vueling | D21: BIO-VLC | E21: Economy | F21: 0 | G21: 426 | H21: 426 | I21: =IF(OR(F21="",F21=0,H21="",H21=0),"",(H21-G21)/F21*100) | J21: =IF(OR(H21="",H21=0),"",MAX(H21-G21,0)) -> 0 | K21: =IF(OR(H21="",H21=0),"",MAX((H21-G21)/H21,0)) -> 0 | L21: VY3972 VF8SUL
B22: 46242 | C22: AF/KLM | D22: VLC-JFK | E22: Business | F22: 268000 | G22: 1744 | H22: 13192 | I22: =IF(OR(F22="",F22=0,H22="",H22=0),"",(H22-G22)/F22*100) -> 4.2716418 | J22: =IF(OR(H22="",H22=0),"",MAX(H22-G22,0)) -> 11448 | K22: =IF(OR(H22="",H22=0),"",MAX((H22-G22)/H22,0)) -> 0.86779867 | L22: Return via Amex
I23: =IF(OR(F23="",F23=0,H23="",H23=0),"",(H23-G23)/F23*100) | J23: =IF(OR(H23="",H23=0),"",MAX(H23-G23,0)) | K23: =IF(OR(H23="",H23=0),"",MAX((H23-G23)/H23,0))
I24: =IF(OR(F24="",F24=0,H24="",H24=0),"",(H24-G24)/F24*100) | J24: =IF(OR(H24="",H24=0),"",MAX(H24-G24,0)) | K24: =IF(OR(H24="",H24=0),"",MAX((H24-G24)/H24,0))
I25: =IF(OR(F25="",F25=0,H25="",H25=0),"",(H25-G25)/F25*100) | J25: =IF(OR(H25="",H25=0),"",MAX(H25-G25,0)) | K25: =IF(OR(H25="",H25=0),"",MAX((H25-G25)/H25,0))
I26: =IF(OR(F26="",F26=0,H26="",H26=0),"",(H26-G26)/F26*100) | J26: =IF(OR(H26="",H26=0),"",MAX(H26-G26,0)) | K26: =IF(OR(H26="",H26=0),"",MAX((H26-G26)/H26,0))
I27: =IF(OR(F27="",F27=0,H27="",H27=0),"",(H27-G27)/F27*100) | J27: =IF(OR(H27="",H27=0),"",MAX(H27-G27,0)) | K27: =IF(OR(H27="",H27=0),"",MAX((H27-G27)/H27,0))
I28: =IF(OR(F28="",F28=0,H28="",H28=0),"",(H28-G28)/F28*100) | J28: =IF(OR(H28="",H28=0),"",MAX(H28-G28,0)) | K28: =IF(OR(H28="",H28=0),"",MAX((H28-G28)/H28,0))
I29: =IF(OR(F29="",F29=0,H29="",H29=0),"",(H29-G29)/F29*100) | J29: =IF(OR(H29="",H29=0),"",MAX(H29-G29,0)) | K29: =IF(OR(H29="",H29=0),"",MAX((H29-G29)/H29,0))
I30: =IF(OR(F30="",F30=0,H30="",H30=0),"",(H30-G30)/F30*100) | J30: =IF(OR(H30="",H30=0),"",MAX(H30-G30,0)) | K30: =IF(OR(H30="",H30=0),"",MAX((H30-G30)/H30,0))
I31: =IF(OR(F31="",F31=0,H31="",H31=0),"",(H31-G31)/F31*100) | J31: =IF(OR(H31="",H31=0),"",MAX(H31-G31,0)) | K31: =IF(OR(H31="",H31=0),"",MAX((H31-G31)/H31,0))
I32: =IF(OR(F32="",F32=0,H32="",H32=0),"",(H32-G32)/F32*100) | J32: =IF(OR(H32="",H32=0),"",MAX(H32-G32,0)) | K32: =IF(OR(H32="",H32=0),"",MAX((H32-G32)/H32,0))
B34: HOTELS
B35: Check-in | C35: Hotel | D35: Location | E35: Nights | F35: Points | G35: Tax + Fee ($) | H35: Sticker ($) | I35: CPP (¢) | J35: Savings ($) | K35: % Off | L35: Notes
B36: 46231 | C36: InterContinental BCN | D36: Barcelona | E36: 4 | F36: 0 | G36: 931.74 | H36: 1981.74 | I36: =IF(OR(F36="",F36=0,H36="",H36=0),"",(H36-G36)/F36*100) | J36: =IF(OR(H36="",H36=0),"",MAX(H36-G36,0)) -> 1050 | K36: =IF(OR(H36="",H36=0),"",MAX((H36-G36)/H36,0)) -> 0.52983742 | L36: CSR + $500 Chase Edit credit
I37: =IF(OR(F37="",F37=0,H37="",H37=0),"",(H37-G37)/F37*100) | J37: =IF(OR(H37="",H37=0),"",MAX(H37-G37,0)) | K37: =IF(OR(H37="",H37=0),"",MAX((H37-G37)/H37,0))
I38: =IF(OR(F38="",F38=0,H38="",H38=0),"",(H38-G38)/F38*100) | J38: =IF(OR(H38="",H38=0),"",MAX(H38-G38,0)) | K38: =IF(OR(H38="",H38=0),"",MAX((H38-G38)/H38,0))
I39: =IF(OR(F39="",F39=0,H39="",H39=0),"",(H39-G39)/F39*100) | J39: =IF(OR(H39="",H39=0),"",MAX(H39-G39,0)) | K39: =IF(OR(H39="",H39=0),"",MAX((H39-G39)/H39,0))
I40: =IF(OR(F40="",F40=0,H40="",H40=0),"",(H40-G40)/F40*100) | J40: =IF(OR(H40="",H40=0),"",MAX(H40-G40,0)) | K40: =IF(OR(H40="",H40=0),"",MAX((H40-G40)/H40,0))
I41: =IF(OR(F41="",F41=0,H41="",H41=0),"",(H41-G41)/F41*100) | J41: =IF(OR(H41="",H41=0),"",MAX(H41-G41,0)) | K41: =IF(OR(H41="",H41=0),"",MAX((H41-G41)/H41,0))
I42: =IF(OR(F42="",F42=0,H42="",H42=0),"",(H42-G42)/F42*100) | J42: =IF(OR(H42="",H42=0),"",MAX(H42-G42,0)) | K42: =IF(OR(H42="",H42=0),"",MAX((H42-G42)/H42,0))
I43: =IF(OR(F43="",F43=0,H43="",H43=0),"",(H43-G43)/F43*100) | J43: =IF(OR(H43="",H43=0),"",MAX(H43-G43,0)) | K43: =IF(OR(H43="",H43=0),"",MAX((H43-G43)/H43,0))
I44: =IF(OR(F44="",F44=0,H44="",H44=0),"",(H44-G44)/F44*100) | J44: =IF(OR(H44="",H44=0),"",MAX(H44-G44,0)) | K44: =IF(OR(H44="",H44=0),"",MAX((H44-G44)/H44,0))
I45: =IF(OR(F45="",F45=0,H45="",H45=0),"",(H45-G45)/F45*100) | J45: =IF(OR(H45="",H45=0),"",MAX(H45-G45,0)) | K45: =IF(OR(H45="",H45=0),"",MAX((H45-G45)/H45,0))
I46: =IF(OR(F46="",F46=0,H46="",H46=0),"",(H46-G46)/F46*100) | J46: =IF(OR(H46="",H46=0),"",MAX(H46-G46,0)) | K46: =IF(OR(H46="",H46=0),"",MAX((H46-G46)/H46,0))
I47: =IF(OR(F47="",F47=0,H47="",H47=0),"",(H47-G47)/F47*100) | J47: =IF(OR(H47="",H47=0),"",MAX(H47-G47,0)) | K47: =IF(OR(H47="",H47=0),"",MAX((H47-G47)/H47,0))
...

Sheet Japan 2027
B2: JAPAN 2027
B4: Trip Name | C4: Japan Trip | E4: Dates | F4: Feb 5 - Feb 21, 2027 | I4: Notes | J4: Tokyo / Sapporo / Kanazawa
B6: TRIP SUMMARY
B7: Total Trip Cost | E7: Cash on Redemptions | H7: Activities Cash | J7: Points Used
B8: =SUM(G18:G32)+SUM(G36:G50)+SUM(H54:H68) -> 1320 | E8: =SUM(G18:G32)+SUM(G36:G50) -> 0 | H8: =SUM(H54:H68) -> 1320 | J8: =SUM(F18:F32)+SUM(F36:F50) -> 0
B10: Sticker Value | E10: Total Savings | H10: Blended CPP | J10: % Off Sticker
B11: =SUM(H18:H32)+SUM(H36:H50) -> 0 | E11: =IFERROR((SUM(H18:H32)+SUM(H36:H50))-(SUM(G18:G32)+SUM(G36:G50)),0) -> 0 | H11: =IFERROR(E11/J8*100,0) -> 0 | J11: =IFERROR(E11/B11,0) -> 0
B13: Airline Points | E13: Airline CPP | H13: Hotel Points | J13: Hotel CPP
B14: =SUM(F18:F32) -> 0 | E14: =IFERROR((SUM(H18:H32)-SUM(G18:G32))/SUM(F18:F32)*100,0) -> 0 | H14: =SUM(F36:F50) -> 0 | J14: =IFERROR((SUM(H36:H50)-SUM(G36:G50))/SUM(F36:F50)*100,0) -> 0
B16: FLIGHTS
B17: Date | C17: Airline | D17: Route | E17: Class | F17: Points | G17: Tax + Fee ($) | H17: Sticker ($) | I17: CPP (¢) | J17: Savings ($) | K17: % Off | L17: Notes
I18: =IF(OR(F18="",F18=0,H18="",H18=0),"",(H18-G18)/F18*100) | J18: =IF(OR(H18="",H18=0),"",MAX(H18-G18,0)) | K18: =IF(OR(H18="",H18=0),"",MAX((H18-G18)/H18,0))
I19: =IF(OR(F19="",F19=0,H19="",H19=0),"",(H19-G19)/F19*100) | J19: =IF(OR(H19="",H19=0),"",MAX(H19-G19,0)) | K19: =IF(OR(H19="",H19=0),"",MAX((H19-G19)/H19,0))
I20: =IF(OR(F20="",F20=0,H20="",H20=0),"",(H20-G20)/F20*100) | J20: =IF(OR(H20="",H20=0),"",MAX(H20-G20,0)) | K20: =IF(OR(H20="",H20=0),"",MAX((H20-G20)/H20,0))
I21: =IF(OR(F21="",F21=0,H21="",H21=0),"",(H21-G21)/F21*100) | J21: =IF(OR(H21="",H21=0),"",MAX(H21-G21,0)) | K21: =IF(OR(H21="",H21=0),"",MAX((H21-G21)/H21,0))
I22: =IF(OR(F22="",F22=0,H22="",H22=0),"",(H22-G22)/F22*100) | J22: =IF(OR(H22="",H22=0),"",MAX(H22-G22,0)) | K22: =IF(OR(H22="",H22=0),"",MAX((H22-G22)/H22,0))
I23: =IF(OR(F23="",F23=0,H23="",H23=0),"",(H23-G23)/F23*100) | J23: =IF(OR(H23="",H23=0),"",MAX(H23-G23,0)) | K23: =IF(OR(H23="",H23=0),"",MAX((H23-G23)/H23,0))
I24: =IF(OR(F24="",F24=0,H24="",H24=0),"",(H24-G24)/F24*100) | J24: =IF(OR(H24="",H24=0),"",MAX(H24-G24,0)) | K24: =IF(OR(H24="",H24=0),"",MAX((H24-G24)/H24,0))
I25: =IF(OR(F25="",F25=0,H25="",H25=0),"",(H25-G25)/F25*100) | J25: =IF(OR(H25="",H25=0),"",MAX(H25-G25,0)) | K25: =IF(OR(H25="",H25=0),"",MAX((H25-G25)/H25,0))
I26: =IF(OR(F26="",F26=0,H26="",H26=0),"",(H26-G26)/F26*100) | J26: =IF(OR(H26="",H26=0),"",MAX(H26-G26,0)) | K26: =IF(OR(H26="",H26=0),"",MAX((H26-G26)/H26,0))
I27: =IF(OR(F27="",F27=0,H27="",H27=0),"",(H27-G27)/F27*100) | J27: =IF(OR(H27="",H27=0),"",MAX(H27-G27,0)) | K27: =IF(OR(H27="",H27=0),"",MAX((H27-G27)/H27,0))
I28: =IF(OR(F28="",F28=0,H28="",H28=0),"",(H28-G28)/F28*100) | J28: =IF(OR(H28="",H28=0),"",MAX(H28-G28,0)) | K28: =IF(OR(H28="",H28=0),"",MAX((H28-G28)/H28,0))
I29: =IF(OR(F29="",F29=0,H29="",H29=0),"",(H29-G29)/F29*100) | J29: =IF(OR(H29="",H29=0),"",MAX(H29-G29,0)) | K29: =IF(OR(H29="",H29=0),"",MAX((H29-G29)/H29,0))
... I32: =IF(OR(F32="",F32=0,H32="",H32=0),"",(H32-G32)/F32*100) | J32: =IF(OR(H32="",H32=0),"",MAX(H32-G32,0)) | K32: =IF(OR(H32="",H32=0),"",MAX((H32-G32)/H32,0))
B34: HOTELS
B35: Check-in | C35: Hotel | D35: Location | E35: Nights | F35: Points | G35: Tax + Fee ($) | H35: Sticker ($) | I35: CPP (¢) | J35: Savings ($) | K35: % Off | L35: Notes
I36: =IF(OR(F36="",F36=0,H36="",H36=0),"",(H36-G36)/F36*100) | J36: =IF(OR(H36="",H36=0),"",MAX(H36-G36,0)) | K36: =IF(OR(H36="",H36=0),"",MAX((H36-G36)/H36,0))
I37: =IF(OR(F37="",F37=0,H37="",H37=0),"",(H37-G37)/F37*100) | J37: =IF(OR(H37="",H37=0),"",MAX(H37-G37,0)) | K37: =IF(OR(H37="",H37=0),"",MAX((H37-G37)/H37,0))
I38: =IF(OR(F38="",F38=0,H38="",H38=0),"",(H38-G38)/F38*100) | J38: =IF(OR(H38="",H38=0),"",MAX(H38-G38,0)) | K38: =IF(OR(H38="",H38=0),"",MAX((H38-G38)/H38,0))
I39: =IF(OR(F39="",F39=0,H39="",H39=0),"",(H39-G39)/F39*100) | J39: =IF(OR(H39="",H39=0),"",MAX(H39-G39,0)) | K39: =IF(OR(H39="",H39=0),"",MAX((H39-G39)/H39,0))
I40: =IF(OR(F40="",F40=0,H40="",H40=0),"",(H40-G40)/F40*100) | J40: =IF(OR(H40="",H40=0),"",MAX(H40-G40,0)) | K40: =IF(OR(H40="",H40=0),"",MAX((H40-G40)/H40,0))
I41: =IF(OR(F41="",F41=0,H41="",H41=0),"",(H41-G41)/F41*100) | J41: =IF(OR(H41="",H41=0),"",MAX(H41-G41,0)) | K41: =IF(OR(H41="",H41=0),"",MAX((H41-G41)/H41,0))
I42: =IF(OR(F42="",F42=0,H42="",H42=0),"",(H42-G42)/F42*100) | J42: =IF(OR(H42="",H42=0),"",MAX(H42-G42,0)) | K42: =IF(OR(H42="",H42=0),"",MAX((H42-G42)/H42,0))
I43: =IF(OR(F43="",F43=0,H43="",H43=0),"",(H43-G43)/F43*100) | J43: =IF(OR(H43="",H43=0),"",MAX(H43-G43,0)) | K43: =IF(OR(H43="",H43=0),"",MAX((H43-G43)/H43,0))
I44: =IF(OR(F44="",F44=0,H44="",H44=0),"",(H44-G44)/F44*100) | J44: =IF(OR(H44="",H44=0),"",MAX(H44-G44,0)) | K44: =IF(OR(H44="",H44=0),"",MAX((H44-G44)/H44,0))
I45: =IF(OR(F45="",F45=0,H45="",H45=0),"",(H45-G45)/F45*100) | J45: =IF(OR(H45="",H45=0),"",MAX(H45-G45,0)) | K45: =IF(OR(H45="",H45=0),"",MAX((H45-G45)/H45,0))
I46: =IF(OR(F46="",F46=0,H46="",H46=0),"",(H46-G46)/F46*100) | J46: =IF(OR(H46="",H46=0),"",MAX(H46-G46,0)) | K46: =IF(OR(H46="",H46=0),"",MAX((H46-G46)/H46,0))
I47: =IF(OR(F47="",F47=0,H47="",H47=0),"",(H47-G47)/F47*100) | J47: =IF(OR(H47="",H47=0),"",MAX(H47-G47,0)) | K47: =IF(OR(H47="",H47=0),"",MAX((H47-G47)/H47,0))
... I50: =IF(OR(F50="",F50=0,H50="",H50=0),"",(H50-G50)/F50*100) | J50: =IF(OR(H50="",H50=0),"",MAX(H50-G50,0)) | K50: =IF(OR(H50="",H50=0),"",MAX((H50-G50)/H50,0))
B52: ACTIVITIES & EXPERIENCES
...

Sheet Cards
B2: Cards — Annual Fee & Bonus Tracker
B3: First Year Net = Bonus Value + Credits Used − Annual Fee.
B5: Card | C5: Open Date | D5: Issuer | E5: AF ($) | F5: Bonus Pts | G5: Min Spend ($) | H5: Bonus Hit? | I5: Bonus Value ($) | J5: Credits Used ($) | K5: First Year Net ($) | L5: AF Renewal Date | M5: Notes
B6: Amex Business Platinum #1 | C6: 44941 | D6: Amex | E6: - | H6: Yes | J6: 1500 | K6: =I6+J6-E6 -> #VALUE! | L6: =IF(C6="","",EDATE(C6,12)) -> 45306 | M6: Biz Plat; Dell + wireless + flight credits
B7: Amex Business Platinum #2 | C7: 45170 | D7: Amex | E7: 695 | H7: Yes | J7: 1200 | K7: =I7+J7-E7 -> 505 | L7: =IF(C7="","",EDATE(C7,12)) -> 45536 | M7: Biz Plat; second line
B8: Amex Business Platinum #3 | C8: 45383 | D8: Amex | E8: - | H8: Yes | J8: 800 | K8: =I8+J8-E8 -> #VALUE! | L8: =IF(C8="","",EDATE(C8,12)) -> 45748 | M8: Biz Plat; third line
B9: Amex Business Gold #1 | C9: 44986 | D9: Amex | E9: 375 | H9: Yes | J9: 240 | K9: =I9+J9-E9 -> -135 | L9: =IF(C9="","",EDATE(C9,12)) -> 45352 | M9: Biz Gold; flexible 4x category
B10: Amex Business Gold #2 | C10: 45292 | D10: Amex | E10: - | H10: Yes | J10: 240 | K10: =I10+J10-E10 -> #VALUE! | L10: =IF(C10="","",EDATE(C10,12)) -> 45658 | M10: Biz Gold; second line
B11: Blue Business Plus #1 | C11: 44713 | D11: Amex | E11: 0 | H11: Yes | J11: 0 | K11: =I11+J11-E11 -> 0 | L11: =IF(C11="","",EDATE(C11,12)) -> 45078 | M11: BBP; 2x everywhere up to $50k/yr
B12: Blue Business Plus #2 | C12: 45505 | D12: Amex | E12: 0 | H12: Yes | J12: 0 | K12: =I12+J12-E12 -> 0 | L12: =IF(C12="","",EDATE(C12,12)) -> 45870 | M12: BBP; second line
B13: Chase Sapphire Reserve | C13: 44927 | D13: Chase | E13: 795 | H13: Yes | J13: 300 | K13: =I13+J13-E13 -> -495 | L13: =IF(C13="","",EDATE(C13,12)) -> 45292 | M13: $300 travel credit; CSR portal 1.5x
B14: Chase Sapphire Preferred | C14: 44713 | D14: Chase | E14: 95 | H14: Yes | J14: 50 | K14: =I14+J14-E14 -> -45 | L14: =IF(C14="","",EDATE(C14,12)) -> 45078 | M14: Long-held; downgrade candidate
B15: Capital One Venture X | C15: 45658 | D15: Capital One | E15: 395 | H15: Yes | J15: 700 | K15: =I15+J15-E15 -> 305 | L15: =IF(C15="","",EDATE(C15,12)) -> 46023 | M15: $300 portal + $100 Global Entry
B16: Capital One Spark | C16: 45352 | D16: Capital One | E16: 150 | H16: — | J16: 0 | K16: =I16+J16-E16 -> -150 | L16: =IF(C16="","",EDATE(C16,12)) -> 45717 | M16: Business card
B17: Bilt 2.0 | C17: 46054 | D17: Wells Fargo | E17: 495 | H17: Yes | J17: 0 | K17: =I17+J17-E17 -> -495 | L17: =IF(C17="","",EDATE(C17,12)) -> 46419 | M17: Mortgage points via UWM
K18: =IF(I18="","",I18+J18-E18) | L18: =IF(C18="","",EDATE(C18,12))
K19: =IF(I19="","",I19+J19-E19) | L19: =IF(C19="","",EDATE(C19,12))
K20: =IF(I20="","",I20+J20-E20) | L20: =IF(C20="","",EDATE(C20,12))
K21: =IF(I21="","",I21+J21-E21) | L21: =IF(C21="","",EDATE(C21,12))
K22: =IF(I22="","",I22+J22-E22) | L22: =IF(C22="","",EDATE(C22,12))
K23: =IF(I23="","",I23+J23-E23) | L23: =IF(C23="","",EDATE(C23,12))
K24: =IF(I24="","",I24+J24-E24) | L24: =IF(C24="","",EDATE(C24,12))
K25: =IF(I25="","",I25+J25-E25) | L25: =IF(C25="","",EDATE(C25,12))
K26: =IF(I26="","",I26+J26-E26) | L26: =IF(C26="","",EDATE(C26,12))
K27: =IF(I27="","",I27+J27-E27) | L27: =IF(C27="","",EDATE(C27,12))
K28: =IF(I28="","",I28+J28-E28) | L28: =IF(C28="","",EDATE(C28,12))
K29: =IF(I29="","",I29+J29-E29) | L29: =IF(C29="","",EDATE(C29,12))
K30: =IF(I30="","",I30+J30-E30) | L30: =IF(C30="","",EDATE(C30,12))
B31: TOTALS | E31: =SUM(E6:E30) -> 3000 | F31: =SUM(F6:F30) -> 0 | G31: =SUM(G6:G30) -> 0 | I31: =SUM(I6:I30) -> 0 | J31: =SUM(J6:J30) -> 5030 | K31: =SUM(K6:K30) -> #VALUE!

Sheet 3% Fee Tracker
B2: 3% Fee Spend Tracker
B3: Daycare, taxes, etc. — non-bonus spend you pay by card. Tracks breakeven and net value.
L5: ASSUMPTIONS
L6: Your CPP (¢) | M6: 1.8
L7: Default fee rate | M7: 0.03
L8: Net = (Pts × CPP) − Fee | M8: Positive = good call
B10: Date | C10: Payee | D10: Category | E10: Card Used | F10: Earn Rate (x) | G10: Charge ($) | H10: Fee Rate | I10: Fee Paid ($) | J10: Points Earned | K10: Points Value ($) | L10: Net Value ($) | M10: Breakeven CPP | N10: Notes
B11: 46037 | C11: Derek's Daycare | D11: Childcare | E11: Amex Biz blue | F11: 2 | G11: 1750 | H11: 0.03 | I11: =G11*H11 -> 52.5 | J11: =G11*F11 -> 3500 | K11: =J11*$M$6/100 -> 63 | L11: =K11-I11 -> 10.5 | M11: =IF(F11=0,"",H11/F11*100) -> 1.5 | N11: Monthly
B12: 46068 | C12: Derek's Daycare | D12: Childcare | E12: Amex Biz blue | F12: 2 | G12: 1750 | H12: 0.03 | I12: =G12*H12 -> 52.5 | J12: =G12*F12 -> 3500 | K12: =J12*$M$6/100 -> 63 | L12: =K12-I12 -> 10.5 | M12: =IF(F12=0,"",H12/F12*100) -> 1.5 | N12: Monthly
B13: 46096 | C13: Derek's Daycare | D13: Childcare | E13: Amex Biz blue | F13: 2 | G13: 1750 | H13: 0.03 | I13: =G13*H13 -> 52.5 | J13: =G13*F13 -> 3500 | K13: =J13*$M$6/100 -> 63 | L13: =K13-I13 -> 10.5 | M13: =IF(F13=0,"",H13/F13*100) -> 1.5 | N13: Monthly
B14: 46127 | C14: Income Tax Q1 | D14: Taxes | E14: Blue Biz Plus # | F14: 2 | G14: 5000 | H14: 0.0187 | I14: =G14*H14 -> 93.5 | J14: =G14*F14 -> 10000 | K14: =J14*$M$6/100 -> 180 | L14: =K14-I14 -> 86.5 | M14: =IF(F14=0,"",H14/F14*100) -> 0.935
B15: 46127 | C15: Income Tax Q1 | D15: Taxes | E15: Amex Biz Gold #1 | F15: 2 | G15: 8000 | H15: 0.019 | I15: =G15*H15 -> 152 | J15: =G15*F15 -> 16000 | K15: =J15*$M$6/100 -> 288 | L15: =K15-I15 -> 136 | M15: =IF(F15=0,"",H15/F15*100) -> 0.95
B16: 46127 | C16: Derek's Daycare | D16: Childcare | E16: Amex Biz Blue | F16: 2 | G16: 1750 | H16: 0.03 | I16: =IF(G16="","",G16*H16) -> 52.5 | J16: =IF(G16="","",G16*F16) -> 3500 | K16: =IF(J16="","",J16*$M$6/100) -> 63 | L16: =IF(K16="","",K16-I16) -> 10.5 | M16: =IF(OR(F16="",F16=0),"",H16/F16*100) -> 1.5 | N16: Monthly
I17: =IF(G17="","",G17*H17) | J17: =IF(G17="","",G17*F17) | K17: =IF(J17="","",J17*$M$6/100) | L17: =IF(K17="","",K17-I17) | M17: =IF(OR(F17="",F17=0),"",H17/F17*100)
I18: =IF(G18="","",G18*H18) | J18: =IF(G18="","",G18*F18) | K18: =IF(J18="","",J18*$M$6/100) | L18: =IF(K18="","",K18-I18) | M18: =IF(OR(F18="",F18=0),"",H18/F18*100)
I19: =IF(G19="","",G19*H19) | J19: =IF(G19="","",G19*F19) | K19: =IF(J19="","",J19*$M$6/100) | L19: =IF(K19="","",K19-I19) | M19: =IF(OR(F19="",F19=0),"",H19/F19*100)
I20: =IF(G20="","",G20*H20) | J20: =IF(G20="","",G20*F20) | K20: =IF(J20="","",J20*$M$6/100) | L20: =IF(K20="","",K20-I20) | M20: =IF(OR(F20="",F20=0),"",H20/F20*100)
I21: =IF(G21="","",G21*H21) | J21: =IF(G21="","",G21*F21) | K21: =IF(J21="","",J21*$M$6/100) | L21: =IF(K21="","",K21-I21) | M21: =IF(OR(F21="",F21=0),"",H21/F21*100)
I22: =IF(G22="","",G22*H22) | J22: =IF(G22="","",G22*F22) | K22: =IF(J22="","",J22*$M$6/100) | L22: =IF(K22="","",K22-I22) | M22: =IF(OR(F22="",F22=0),"",H22/F22*100)
I23: =IF(G23="","",G23*H23) | J23: =IF(G23="","",G23*F23) | K23: =IF(J23="","",J23*$M$6/100) | L23: =IF(K23="","",K23-I23) | M23: =IF(OR(F23="",F23=0),"",H23/F23*100)
I24: =IF(G24="","",G24*H24) | J24: =IF(G24="","",G24*F24) | K24: =IF(J24="","",J24*$M$6/100) | L24: =IF(K24="","",K24-I24) | M24: =IF(OR(F24="",F24=0),"",H24/F24*100)
I25: =IF(G25="","",G25*H25) | J25: =IF(G25="","",G25*F25) | K25: =IF(J25="","",J25*$M$6/100) | L25: =IF(K25="","",K25-I25) | M25: =IF(OR(F25="",F25=0),"",H25/F25*100)
I26: =IF(G26="","",G26*H26) | J26: =IF(G26="","",G26*F26) | K26: =IF(J26="","",J26*$M$6/100) | L26: =IF(K26="","",K26-I26) | M26: =IF(OR(F26="",F26=0),"",H26/F26*100)
I27: =IF(G27="","",G27*H27) | J27: =IF(G27="","",G27*F27) | K27: =IF(J27="","",J27*$M$6/100) | L27: =IF(K27="","",K27-I27) | M27: =IF(OR(F27="",F27=0),"",H27/F27*100)
I28: =IF(G28="","",G28*H28) | J28: =IF(G28="","",G28*F28) | K28: =IF(J28="","",J28*$M$6/100) | L28: =IF(K28="","",K28-I28) | M28: =IF(OR(F28="",F28=0),"",H28/F28*100)
... I59: =IF(G59="","",G59*H59) | J59: =IF(G59="","",G59*F59) | K59: =IF(J59="","",J59*$M$6/100) | L59: =IF(K59="","",K59-I59) | M59: =IF(OR(F59="",F59=0),"",H59/F59*100)
B61: TOTALS | G61: =SUM(G11:G60) -> 20000 | I61: =SUM(I11:I60) -> 455.5 | J61: =SUM(J11:J60) -> 40000 | K61: =SUM(K11:K60) -> 720 | L61: =SUM(L11:L60) -> 264.5

Sheet CPP Calculator
B2: Cents Per Point Calculator
B3: Quick cash vs. points decision for any single booking.
B5: INPUTS | E5: OUTPUTS
B6: Cash Price ($) | C6: 2792 | E6: Net cash saved by using points | F6: =C6-C7 -> 2792
B7: Taxes + Fees if using points ($) | C7: 0 | E7: Cents per point delivered | F7: =IF(C8=0,0,(C6-C7)/C8*100) -> 1.6232558
B8: Points Required | C8: 172000 | E8: Verdict | F8: =IF(C8=0,"Enter points",IF((C6-C7)/C8*100>=C9,"✓ Good redemption","✗ Below target — pay cash")) -> ✓ Good redemption
B9: Your Target CPP (¢) | C9: 1.5 | E9: Points value at your target CPP | F9: =C8*C9/100 -> 2580
B11: REFERENCE — typical CPP benchmarks
B12: Chase UR — transfer to partners | C12: 1.5 - 2.5¢
B13: Chase UR — CSR portal | C13: 1.5¢
B14: Amex MR — transfer to airlines | C14: 1.5 - 2¢
B15: Amex MR — Pay With Points | C15: 0.7¢
B16: Capital One Miles — transfer | C16: 1.4 - 1.85¢
B17: Capital One — travel portal | C17: 1.0¢
B18: Hilton Honors | C18: 0.4 - 0.6¢
B19: Marriott Bonvoy | C19: 0.7 - 0.9¢
B20: Bilt — transfer to partners | C20: 1.5 - 2¢
